Workbook

Sheet Readme
A1: Campaign Analysis — Cold Email Insights
A3: Source: metrics.json generated 2026-05-21T22:06:09.167162Z
A4: Benchmark: Manufacturing
A5: How it works:
A6: • The Variables sheet is the single source of truth — one row per Sequencer campaign
A7: with raw counts (emails / leads / replied / bounced / interested / demos / shows /
A8: pending / no-shows / completed / closed / ARR / MRR).
A9: • Every industry tab uses SUMIFS to aggregate those raw counts by industry.
A10: • Ratios are computed live as numerator-sum / denominator-sum via IFERROR(...).
A11: • To re-run with fresh data, run: python3 campaign_analysis.py
A13: Definitions:
A14: Emails Sent — total deliveries from campaign-stats snapshot
... A26: Index vs MFG = industry value ÷ Manufacturing value (column D on every industry tab)

Sheet Variables
A1: campaign_id | B1: campaign_name | C1: industry | D1: industry_group | E1: status | F1: emails_sent | G1: leads_contacted | H1: replied | I1: bounced | J1: interested | K1: demos_booked | L1: showups | M1: pending | N1: noshow | O1: completed_demos | P1: closed | Q1: arr | R1: mrr
A2: 115 | B2: Business Services (1-5) - Google → Google (20_05) | C2: Business Services (1-5) | D2: Business Services (1-5) | E2: active | F2: 8024 | G2: 8024 | H2: 172 | I2: 108 | J2: 38 | K2: 9 | L2: 0 | M2: 7 | N2: 2 | O2: 2 | P2: 0 | Q2: 0 | R2: 0
A3: 116 | B3: Business Services (1-5) - Google → Custom+Misc (20_05) | C3: Business Services (1-5) | D3: Business Services (1-5) | E3: active | F3: 5936 | G3: 5936 | H3: 125 | I3: 124 | J3: 34 | K3: 4 | L3: 0 | M3: 3 | N3: 1 | O3: 1 | P3: 0 | Q3: 0 | R3: 0
A4: 117 | B4: Business Services (1-5) - Microsoft → Outlook (20_05) | C4: Business Services (1-5) | D4: Business Services (1-5) | E4: active | F4: 2896 | G4: 2896 | H4: 7 | I4: 10 | J4: 2 | K4: 0 | L4: 0 | M4: 0 | N4: 0 | O4: 0 | P4: 0 | Q4: 0 | R4: 0
A5: 112 | B5: Mix Services (1-5) - Google → Google (19_05) | C5: Mix Services (1-5) | D5: Mix Services (1-5) | E5: active | F5: 16806 | G5: 9715 | H5: 209 | I5: 132 | J5: 35 | K5: 8 | L5: 2 | M5: 5 | N5: 1 | O5: 3 | P5: 0 | Q5: 0 | R5: 0
A6: 113 | B6: Mix Services (1-5) - Google → Custom+Misc (19_05) | C6: Mix Services (1-5) | D6: Mix Services (1-5) | E6: active | F6: 11685 | G6: 6985 | H6: 110 | I6: 280 | J6: 14 | K6: 3 | L6: 2 | M6: 1 | N6: 0 | O6: 2 | P6: 1 | Q6: 6000 | R6: 500
A7: 114 | B7: Mix Services (1-5) - Microsoft → Outlook (19_05) | C7: Mix Services (1-5) | D7: Mix Services (1-5) | E7: active | F7: 8474 | G7: 6351 | H7: 39 | I7: 1226 | J7: 6 | K7: 1 | L7: 0 | M7: 1 | N7: 0 | O7: 0 | P7: 0 | Q7: 0 | R7: 0
A8: 110 | B8: Mix Services (5-200) - Microsoft → Outlook (19_05) | C8: Mix Services (5-200) | D8: Mix Services (5-200) | E8: active | F8: 12879 | G8: 11819 | H8: 30 | I8: 1486 | J8: 1 | K8: 0 | L8: 0 | M8: 0 | N8: 0 | O8: 0 | P8: 0 | Q8: 0 | R8: 0
A9: 109 | B9: Mix Services (5-200) - Google → Custom+Misc (19_05) | C9: Mix Services (5-200) | D9: Mix Services (5-200) | E9: active | F9: 12585 | G9: 7300 | H9: 112 | I9: 264 | J9: 3 | K9: 2 | L9: 0 | M9: 1 | N9: 1 | O9: 1 | P9: 0 | Q9: 0 | R9: 0
A10: 108 | B10: Mix Services (5-200) - Google → Google (19_05) | C10: Mix Services (5-200) | D10: Mix Services (5-200) | E10: active | F10: 17908 | G10: 12321 | H10: 254 | I10: 57 | J10: 14 | K10: 2 | L10: 0 | M10: 0 | N10: 2 | O10: 2 | P10: 0 | Q10: 0 | R10: 0
A11: 107 | B11: MFG SE Hook - Google → Custom+Misc (15_05) | C11: MFG SE Hook | D11: MFG SE Hook | E11: active | F11: 11253 | G11: 6902 | H11: 188 | I11: 133 | J11: 4 | K11: 1 | L11: 0 | M11: 1 | N11: 0 | O11: 0 | P11: 0 | Q11: 0 | R11: 0
A12: 106 | B12: MFG SE Hook - Google → Google (15_05) | C12: MFG SE Hook | D12: MFG SE Hook | E12: active | F12: 4904 | G12: 2649 | H12: 71 | I12: 16 | J12: 1 | K12: 1 | L12: 0 | M12: 0 | N12: 1 | O12: 1 | P12: 0 | Q12: 0 | R12: 0
A13: 105 | B13: MFG SE Hook - Microsoft → Outlook (15_05) | C13: MFG SE Hook | D13: MFG SE Hook | E13: active | F13: 600 | G13: 590 | H13: 16 | I13: 14 | J13: 0 | K13: 0 | L13: 0 | M13: 0 | N13: 0 | O13: 0 | P13: 0 | Q13: 0 | R13: 0
... A47: 1 | B47: MFG Outbound 1 | C47: Manufacturing | D47: Manufacturing | E47: completed | F47: 1 | G47: 1 | H47: 4 | I47: 0 | J47: 1 | K47: 3 | L47: 0 | M47: 0 | N47: 3 | O47: 3 | P47: 0 | Q47: 0 | R47: 0

Sheet Business Services (1-5)
A1: Industry | B1: Cell ref
A2: Business Services (1-5) | B2: used by all formulas below ↓
A4: Metric | B4: Business Services (1-5) | C4: Manufacturing (benchmark) | D4: Index vs MFG
A5: EMAIL
A6: Emails Sent | B6: =SUMIFS(Variables!F2:F47, Variables!C2:C47,"Business Services (1-5)") | C6: =SUMIFS(Variables!F2:F47, Variables!C2:C47,"Manufacturing") | D6: =IFERROR(B6/C6,"")
A7: Leads Contacted | B7: =SUMIFS(Variables!G2:G47, Variables!C2:C47,"Business Services (1-5)") | C7: =SUMIFS(Variables!G2:G47, Variables!C2:C47,"Manufacturing") | D7: =IFERROR(B7/C7,"")
A8: Replied (total) | B8: =SUMIFS(Variables!H2:H47, Variables!C2:C47,"Business Services (1-5)") | C8: =SUMIFS(Variables!H2:H47, Variables!C2:C47,"Manufacturing") | D8: =IFERROR(B8/C8,"")
A9: Reply Rate (per lead) | B9: =IFERROR((SUMIFS(Variables!H2:H47, Variables!C2:C47,"Business Services (1-5)"))/(SUMIFS(Variables!G2:G47, Variables!C2:C47,"Business Services (1-5)")),0) | C9: =IFERROR((SUMIFS(Variables!H2:H47, Variables!C2:C47,"Manufacturing"))/(SUMIFS(Variables!G2:G47, Variables!C2:C47,"Manufacturing")),0) | D9: =IFERROR(B9/C9,"")
A10: Bounced | B10: =SUMIFS(Variables!I2:I47, Variables!C2:C47,"Business Services (1-5)") | C10: =SUMIFS(Variables!I2:I47, Variables!C2:C47,"Manufacturing") | D10: =IFERROR(B10/C10,"")
A11: Bounce % (per lead) | B11: =IFERROR((SUMIFS(Variables!I2:I47, Variables!C2:C47,"Business Services (1-5)"))/(SUMIFS(Variables!G2:G47, Variables!C2:C47,"Business Services (1-5)")),0) | C11: =IFERROR((SUMIFS(Variables!I2:I47, Variables!C2:C47,"Manufacturing"))/(SUMIFS(Variables!G2:G47, Variables!C2:C47,"Manufacturing")),0) | D11: =IFERROR(B11/C11,"")
A12: Interested Replies | B12: =SUMIFS(Variables!J2:J47, Variables!C2:C47,"Business Services (1-5)") | C12: =SUMIFS(Variables!J2:J47, Variables!C2:C47,"Manufacturing") | D12: =IFERROR(B12/C12,"")
A13: Interest Rate (per lead) | B13: =IFERROR((SUMIFS(Variables!J2:J47, Variables!C2:C47,"Business Services (1-5)"))/(SUMIFS(Variables!G2:G47, Variables!C2:C47,"Business Services (1-5)")),0) | C13: =IFERROR((SUMIFS(Variables!J2:J47, Variables!C2:C47,"Manufacturing"))/(SUMIFS(Variables!G2:G47, Variables!C2:C47,"Manufacturing")),0) | D13: =IFERROR(B13/C13,"")
A14: DEMOS
A15: Demos Booked | B15: =SUMIFS(Variables!K2:K47, Variables!C2:C47,"Business Services (1-5)") | C15: =SUMIFS(Variables!K2:K47, Variables!C2:C47,"Manufacturing") | D15: =IFERROR(B15/C15,"")
A16: Pending Demos | B16: =SUMIFS(Variables!M2:M47, Variables!C2:C47,"Business Services (1-5)") | C16: =SUMIFS(Variables!M2:M47, Variables!C2:C47,"Manufacturing") | D16: =IFERROR(B16/C16,"")
A17: Demos / Emails Sent | B17: =IFERROR((SUMIFS(Variables!K2:K47, Variables!C2:C47,"Business Services (1-5)"))/(SUMIFS(Variables!F2:F47, Variables!C2:C47,"Business Services (1-5)")),0) | C17: =IFERROR((SUMIFS(Variables!K2:K47, Variables!C2:C47,"Manufacturing"))/(SUMIFS(Variables!F2:F47, Variables!C2:C47,"Manufacturing")),0) | D17: =IFERROR(B17/C17,"")
A18: Demos / Leads Contacted | B18: =IFERROR((SUMIFS(Variables!K2:K47, Variables!C2:C47,"Business Services (1-5)"))/(SUMIFS(Variables!G2:G47, Variables!C2:C47,"Business Services (1-5)")),0) | C18: =IFERROR((SUMIFS(Variables!K2:K47, Variables!C2:C47,"Manufacturing"))/(SUMIFS(Variables!G2:G47, Variables!C2:C47,"Manufacturing")),0) | D18: =IFERROR(B18/C18,"")
A19: Demos / Interested | B19: =IFERROR((SUMIFS(Variables!K2:K47, Variables!C2:C47,"Business Services (1-5)"))/(SUMIFS(Variables!J2:J47, Variables!C2:C47,"Business Services (1-5)")),0) | C19: =IFERROR((SUMIFS(Variables!K2:K47, Variables!C2:C47,"Manufacturing"))/(SUMIFS(Variables!J2:J47, Variables!C2:C47,"Manufacturing")),0) | D19: =IFERROR(B19/C19,"")
A20: SHOW-UPS
A21: Total Show-ups | B21: =SUMIFS(Variables!L2:L47, Variables!C2:C47,"Business Services (1-5)") | C21: =SUMIFS(Variables!L2:L47, Variables!C2:C47,"Manufacturing") | D21: =IFERROR(B21/C21,"")
A22: No-shows | B22: =SUMIFS(Variables!N2:N47, Variables!C2:C47,"Business Services (1-5)") | C22: =SUMIFS(Variables!N2:N47, Variables!C2:C47,"Manufacturing") | D22: =IFERROR(B22/C22,"")
A23: Show-ups / Emails Sent | B23: =IFERROR((SUMIFS(Variables!L2:L47, Variables!C2:C47,"Business Services (1-5)"))/(SUMIFS(Variables!F2:F47, Variables!C2:C47,"Business Services (1-5)")),0) | C23: =IFERROR((SUMIFS(Variables!L2:L47, Variables!C2:C47,"Manufacturing"))/(SUMIFS(Variables!F2:F47, Variables!C2:C47,"Manufacturing")),0) | D23: =IFERROR(B23/C23,"")
A24: Show-ups / Leads Contacted | B24: =IFERROR((SUMIFS(Variables!L2:L47, Variables!C2:C47,"Business Services (1-5)"))/(SUMIFS(Variables!G2:G47, Variables!C2:C47,"Business Services (1-5)")),0) | C24: =IFERROR((SUMIFS(Variables!L2:L47, Variables!C2:C47,"Manufacturing"))/(SUMIFS(Variables!G2:G47, Variables!C2:C47,"Manufacturing")),0) | D24: =IFERROR(B24/C24,"")
A25: Show-up Rate (Shows / Completed) | B25: =IFERROR((SUMIFS(Variables!L2:L47, Variables!C2:C47,"Business Services (1-5)"))/(SUMIFS(Variables!O2:O47, Variables!C2:C47,"Business Services (1-5)")),0) | C25: =IFERROR((SUMIFS(Variables!L2:L47, Variables!C2:C47,"Manufacturing"))/(SUMIFS(Variables!O2:O47, Variables!C2:C47,"Manufacturing")),0) | D25: =IFERROR(B25/C25,"")
A26: Show-ups / Interested | B26: =IFERROR((SUMIFS(Variables!L2:L47, Variables!C2:C47,"Business Services (1-5)"))/(SUMIFS(Variables!J2:J47, Variables!C2:C47,"Business Services (1-5)")),0) | C26: =IFERROR((SUMIFS(Variables!L2:L47, Variables!C2:C47,"Manufacturing"))/(SUMIFS(Variables!J2:J47, Variables!C2:C47,"Manufacturing")),0) | D26: =IFERROR(B26/C26,"")
A27: CLOSED (ONBOARDINGS)
A28: Closed Deals | B28: =SUMIFS(Variables!P2:P47, Variables!C2:C47,"Business Services (1-5)") | C28: =SUMIFS(Variables!P2:P47, Variables!C2:C47,"Manufacturing") | D28: =IFERROR(B28/C28,"")
A29: ARR | B29: =SUMIFS(Variables!Q2:Q47, Variables!C2:C47,"Business Services (1-5)") | C29: =SUMIFS(Variables!Q2:Q47, Variables!C2:C47,"Manufacturing") | D29: =IFERROR(B29/C29,"")
A30: MRR | B30: =SUMIFS(Variables!R2:R47, Variables!C2:C47,"Business Services (1-5)") | C30: =SUMIFS(Variables!R2:R47, Variables!C2:C47,"Manufacturing") | D30: =IFERROR(B30/C30,"")
A31: Close / Demo | B31: =IFERROR((SUMIFS(Variables!P2:P47, Variables!C2:C47,"Business Services (1-5)"))/(SUMIFS(Variables!K2:K47, Variables!C2:C47,"Business Services (1-5)")),0) | C31: =IFERROR((SUMIFS(Variables!P2:P47, Variables!C2:C47,"Manufacturing"))/(SUMIFS(Variables!K2:K47, Variables!C2:C47,"Manufacturing")),0) | D31: =IFERROR(B31/C31,"")
A32: Close / Show-up | B32: =IFERROR((SUMIFS(Variables!P2:P47, Variables!C2:C47,"Business Services (1-5)"))/(SUMIFS(Variables!L2:L47, Variables!C2:C47,"Business Services (1-5)")),0) | C32: =IFERROR((SUMIFS(Variables!P2:P47, Variables!C2:C47,"Manufacturing"))/(SUMIFS(Variables!L2:L47, Variables!C2:C47,"Manufacturing")),0) | D32: =IFERROR(B32/C32,"")
A33: Close / Interested | B33: =IFERROR((SUMIFS(Variables!P2:P47, Variables!C2:C47,"Business Services (1-5)"))/(SUMIFS(Variables!J2:J47, Variables!C2:C47,"Business Services (1-5)")),0) | C33: =IFERROR((SUMIFS(Variables!P2:P47, Variables!C2:C47,"Manufacturing"))/(SUMIFS(Variables!J2:J47, Variables!C2:C47,"Manufacturing")),0) | D33: =IFERROR(B33/C33,"")
A34: Close / Lead | B34: =IFERROR((SUMIFS(Variables!P2:P47, Variables!C2:C47,"Business Services (1-5)"))/(SUMIFS(Variables!G2:G47, Variables!C2:C47,"Business Services (1-5)")),0) | C34: =IFERROR((SUMIFS(Variables!P2:P47, Variables!C2:C47,"Manufacturing"))/(SUMIFS(Variables!G2:G47, Variables!C2:C47,"Manufacturing")),0) | D34: =IFERROR(B34/C34,"")

Sheet Mix Services (1-5)
A1: Industry | B1: Cell ref
A2: Mix Services (1-5) | B2: used by all formulas below ↓
A4: Metric | B4: Mix Services (1-5) | C4: Manufacturing (benchmark) | D4: Index vs MFG
A5: EMAIL
A6: Emails Sent | B6: =SUMIFS(Variables!F2:F47, Variables!C2:C47,"Mix Services (1-5)") | C6: =SUMIFS(Variables!F2:F47, Variables!C2:C47,"Manufacturing") | D6: =IFERROR(B6/C6,"")
A7: Leads Contacted | B7: =SUMIFS(Variables!G2:G47, Variables!C2:C47,"Mix Services (1-5)") | C7: =SUMIFS(Variables!G2:G47, Variables!C2:C47,"Manufacturing") | D7: =IFERROR(B7/C7,"")
A8: Replied (total) | B8: =SUMIFS(Variables!H2:H47, Variables!C2:C47,"Mix Services (1-5)") | C8: =SUMIFS(Variables!H2:H47, Variables!C2:C47,"Manufacturing") | D8: =IFERROR(B8/C8,"")
A9: Reply Rate (per lead) | B9: =IFERROR((SUMIFS(Variables!H2:H47, Variables!C2:C47,"Mix Services (1-5)"))/(SUMIFS(Variables!G2:G47, Variables!C2:C47,"Mix Services (1-5)")),0) | C9: =IFERROR((SUMIFS(Variables!H2:H47, Variables!C2:C47,"Manufacturing"))/(SUMIFS(Variables!G2:G47, Variables!C2:C47,"Manufacturing")),0) | D9: =IFERROR(B9/C9,"")
A10: Bounced | B10: =SUMIFS(Variables!I2:I47, Variables!C2:C47,"Mix Services (1-5)") | C10: =SUMIFS(Variables!I2:I47, Variables!C2:C47,"Manufacturing") | D10: =IFERROR(B10/C10,"")
A11: Bounce % (per lead) | B11: =IFERROR((SUMIFS(Variables!I2:I47, Variables!C2:C47,"Mix Services (1-5)"))/(SUMIFS(Variables!G2:G47, Variables!C2:C47,"Mix Services (1-5)")),0) | C11: =IFERROR((SUMIFS(Variables!I2:I47, Variables!C2:C47,"Manufacturing"))/(SUMIFS(Variables!G2:G47, Variables!C2:C47,"Manufacturing")),0) | D11: =IFERROR(B11/C11,"")
A12: Interested Replies | B12: =SUMIFS(Variables!J2:J47, Variables!C2:C47,"Mix Services (1-5)") | C12: =SUMIFS(Variables!J2:J47, Variables!C2:C47,"Manufacturing") | D12: =IFERROR(B12/C12,"")
A13: Interest Rate (per lead) | B13: =IFERROR((SUMIFS(Variables!J2:J47, Variables!C2:C47,"Mix Services (1-5)"))/(SUMIFS(Variables!G2:G47, Variables!C2:C47,"Mix Services (1-5)")),0) | C13: =IFERROR((SUMIFS(Variables!J2:J47, Variables!C2:C47,"Manufacturing"))/(SUMIFS(Variables!G2:G47, Variables!C2:C47,"Manufacturing")),0) | D13: =IFERROR(B13/C13,"")
A14: DEMOS
A15: Demos Booked | B15: =SUMIFS(Variables!K2:K47, Variables!C2:C47,"Mix Services (1-5)") | C15: =SUMIFS(Variables!K2:K47, Variables!C2:C47,"Manufacturing") | D15: =IFERROR(B15/C15,"")
A16: Pending Demos | B16: =SUMIFS(Variables!M2:M47, Variables!C2:C47,"Mix Services (1-5)") | C16: =SUMIFS(Variables!M2:M47, Variables!C2:C47,"Manufacturing") | D16: =IFERROR(B16/C16,"")
A17: Demos / Emails Sent | B17: =IFERROR((SUMIFS(Variables!K2:K47, Variables!C2:C47,"Mix Services (1-5)"))/(SUMIFS(Variables!F2:F47, Variables!C2:C47,"Mix Services (1-5)")),0) | C17: =IFERROR((SUMIFS(Variables!K2:K47, Variables!C2:C47,"Manufacturing"))/(SUMIFS(Variables!F2:F47, Variables!C2:C47,"Manufacturing")),0) | D17: =IFERROR(B17/C17,"")
A18: Demos / Leads Contacted | B18: =IFERROR((SUMIFS(Variables!K2:K47, Variables!C2:C47,"Mix Services (1-5)"))/(SUMIFS(Variables!G2:G47, Variables!C2:C47,"Mix Services (1-5)")),0) | C18: =IFERROR((SUMIFS(Variables!K2:K47, Variables!C2:C47,"Manufacturing"))/(SUMIFS(Variables!G2:G47, Variables!C2:C47,"Manufacturing")),0) | D18: =IFERROR(B18/C18,"")
A19: Demos / Interested | B19: =IFERROR((SUMIFS(Variables!K2:K47, Variables!C2:C47,"Mix Services (1-5)"))/(SUMIFS(Variables!J2:J47, Variables!C2:C47,"Mix Services (1-5)")),0) | C19: =IFERROR((SUMIFS(Variables!K2:K47, Variables!C2:C47,"Manufacturing"))/(SUMIFS(Variables!J2:J47, Variables!C2:C47,"Manufacturing")),0) | D19: =IFERROR(B19/C19,"")
A20: SHOW-UPS
A21: Total Show-ups | B21: =SUMIFS(Variables!L2:L47, Variables!C2:C47,"Mix Services (1-5)") | C21: =SUMIFS(Variables!L2:L47, Variables!C2:C47,"Manufacturing") | D21: =IFERROR(B21/C21,"")
A22: No-shows | B22: =SUMIFS(Variables!N2:N47, Variables!C2:C47,"Mix Services (1-5)") | C22: =SUMIFS(Variables!N2:N47, Variables!C2:C47,"Manufacturing") | D22: =IFERROR(B22/C22,"")
A23: Show-ups / Emails Sent | B23: =IFERROR((SUMIFS(Variables!L2:L47, Variables!C2:C47,"Mix Services (1-5)"))/(SUMIFS(Variables!F2:F47, Variables!C2:C47,"Mix Services (1-5)")),0) | C23: =IFERROR((SUMIFS(Variables!L2:L47, Variables!C2:C47,"Manufacturing"))/(SUMIFS(Variables!F2:F47, Variables!C2:C47,"Manufacturing")),0) | D23: =IFERROR(B23/C23,"")
A24: Show-ups / Leads Contacted | B24: =IFERROR((SUMIFS(Variables!L2:L47, Variables!C2:C47,"Mix Services (1-5)"))/(SUMIFS(Variables!G2:G47, Variables!C2:C47,"Mix Services (1-5)")),0) | C24: =IFERROR((SUMIFS(Variables!L2:L47, Variables!C2:C47,"Manufacturing"))/(SUMIFS(Variables!G2:G47, Variables!C2:C47,"Manufacturing")),0) | D24: =IFERROR(B24/C24,"")
A25: Show-up Rate (Shows / Completed) | B25: =IFERROR((SUMIFS(Variables!L2:L47, Variables!C2:C47,"Mix Services (1-5)"))/(SUMIFS(Variables!O2:O47, Variables!C2:C47,"Mix Services (1-5)")),0) | C25: =IFERROR((SUMIFS(Variables!L2:L47, Variables!C2:C47,"Manufacturing"))/(SUMIFS(Variables!O2:O47, Variables!C2:C47,"Manufacturing")),0) | D25: =IFERROR(B25/C25,"")
A26: Show-ups / Interested | B26: =IFERROR((SUMIFS(Variables!L2:L47, Variables!C2:C47,"Mix Services (1-5)"))/(SUMIFS(Variables!J2:J47, Variables!C2:C47,"Mix Services (1-5)")),0) | C26: =IFERROR((SUMIFS(Variables!L2:L47, Variables!C2:C47,"Manufacturing"))/(SUMIFS(Variables!J2:J47, Variables!C2:C47,"Manufacturing")),0) | D26: =IFERROR(B26/C26,"")
A27: CLOSED (ONBOARDINGS)
A28: Closed Deals | B28: =SUMIFS(Variables!P2:P47, Variables!C2:C47,"Mix Services (1-5)") | C28: =SUMIFS(Variables!P2:P47, Variables!C2:C47,"Manufacturing") | D28: =IFERROR(B28/C28,"")
A29: ARR | B29: =SUMIFS(Variables!Q2:Q47, Variables!C2:C47,"Mix Services (1-5)") | C29: =SUMIFS(Variables!Q2:Q47, Variables!C2:C47,"Manufacturing") | D29: =IFERROR(B29/C29,"")
A30: MRR | B30: =SUMIFS(Variables!R2:R47, Variables!C2:C47,"Mix Services (1-5)") | C30: =SUMIFS(Variables!R2:R47, Variables!C2:C47,"Manufacturing") | D30: =IFERROR(B30/C30,"")
A31: Close / Demo | B31: =IFERROR((SUMIFS(Variables!P2:P47, Variables!C2:C47,"Mix Services (1-5)"))/(SUMIFS(Variables!K2:K47, Variables!C2:C47,"Mix Services (1-5)")),0) | C31: =IFERROR((SUMIFS(Variables!P2:P47, Variables!C2:C47,"Manufacturing"))/(SUMIFS(Variables!K2:K47, Variables!C2:C47,"Manufacturing")),0) | D31: =IFERROR(B31/C31,"")
A32: Close / Show-up | B32: =IFERROR((SUMIFS(Variables!P2:P47, Variables!C2:C47,"Mix Services (1-5)"))/(SUMIFS(Variables!L2:L47, Variables!C2:C47,"Mix Services (1-5)")),0) | C32: =IFERROR((SUMIFS(Variables!P2:P47, Variables!C2:C47,"Manufacturing"))/(SUMIFS(Variables!L2:L47, Variables!C2:C47,"Manufacturing")),0) | D32: =IFERROR(B32/C32,"")
A33: Close / Interested | B33: =IFERROR((SUMIFS(Variables!P2:P47, Variables!C2:C47,"Mix Services (1-5)"))/(SUMIFS(Variables!J2:J47, Variables!C2:C47,"Mix Services (1-5)")),0) | C33: =IFERROR((SUMIFS(Variables!P2:P47, Variables!C2:C47,"Manufacturing"))/(SUMIFS(Variables!J2:J47, Variables!C2:C47,"Manufacturing")),0) | D33: =IFERROR(B33/C33,"")
A34: Close / Lead | B34: =IFERROR((SUMIFS(Variables!P2:P47, Variables!C2:C47,"Mix Services (1-5)"))/(SUMIFS(Variables!G2:G47, Variables!C2:C47,"Mix Services (1-5)")),0) | C34: =IFERROR((SUMIFS(Variables!P2:P47, Variables!C2:C47,"Manufacturing"))/(SUMIFS(Variables!G2:G47, Variables!C2:C47,"Manufacturing")),0) | D34: =IFERROR(B34/C34,"")

Sheet Mix Services (5-200)
A1: Industry | B1: Cell ref
A2: Mix Services (5-200) | B2: used by all formulas below ↓
A4: Metric | B4: Mix Services (5-200) | C4: Manufacturing (benchmark) | D4: Index vs MFG
A5: EMAIL
A6: Emails Sent | B6: =SUMIFS(Variables!F2:F47, Variables!C2:C47,"Mix Services (5-200)") | C6: =SUMIFS(Variables!F2:F47, Variables!C2:C47,"Manufacturing") | D6: =IFERROR(B6/C6,"")
A7: Leads Contacted | B7: =SUMIFS(Variables!G2:G47, Variables!C2:C47,"Mix Services (5-200)") | C7: =SUMIFS(Variables!G2:G47, Variables!C2:C47,"Manufacturing") | D7: =IFERROR(B7/C7,"")
A8: Replied (total) | B8: =SUMIFS(Variables!H2:H47, Variables!C2:C47,"Mix Services (5-200)") | C8: =SUMIFS(Variables!H2:H47, Variables!C2:C47,"Manufacturing") | D8: =IFERROR(B8/C8,"")
A9: Reply Rate (per lead) | B9: =IFERROR((SUMIFS(Variables!H2:H47, Variables!C2:C47,"Mix Services (5-200)"))/(SUMIFS(Variables!G2:G47, Variables!C2:C47,"Mix Services (5-200)")),0) | C9: =IFERROR((SUMIFS(Variables!H2:H47, Variables!C2:C47,"Manufacturing"))/(SUMIFS(Variables!G2:G47, Variables!C2:C47,"Manufacturing")),0) | D9: =IFERROR(B9/C9,"")
A10: Bounced | B10: =SUMIFS(Variables!I2:I47, Variables!C2:C47,"Mix Services (5-200)") | C10: =SUMIFS(Variables!I2:I47, Variables!C2:C47,"Manufacturing") | D10: =IFERROR(B10/C10,"")
A11: Bounce % (per lead) | B11: =IFERROR((SUMIFS(Variables!I2:I47, Variables!C2:C47,"Mix Services (5-200)"))/(SUMIFS(Variables!G2:G47, Variables!C2:C47,"Mix Services (5-200)")),0) | C11: =IFERROR((SUMIFS(Variables!I2:I47, Variables!C2:C47,"Manufacturing"))/(SUMIFS(Variables!G2:G47, Variables!C2:C47,"Manufacturing")),0) | D11: =IFERROR(B11/C11,"")
A12: Interested Replies | B12: =SUMIFS(Variables!J2:J47, Variables!C2:C47,"Mix Services (5-200)") | C12: =SUMIFS(Variables!J2:J47, Variables!C2:C47,"Manufacturing") | D12: =IFERROR(B12/C12,"")
A13: Interest Rate (per lead) | B13: =IFERROR((SUMIFS(Variables!J2:J47, Variables!C2:C47,"Mix Services (5-200)"))/(SUMIFS(Variables!G2:G47, Variables!C2:C47,"Mix Services (5-200)")),0) | C13: =IFERROR((SUMIFS(Variables!J2:J47, Variables!C2:C47,"Manufacturing"))/(SUMIFS(Variables!G2:G47, Variables!C2:C47,"Manufacturing")),0) | D13: =IFERROR(B13/C13,"")
A14: DEMOS
A15: Demos Booked | B15: =SUMIFS(Variables!K2:K47, Variables!C2:C47,"Mix Services (5-200)") | C15: =SUMIFS(Variables!K2:K47, Variables!C2:C47,"Manufacturing") | D15: =IFERROR(B15/C15,"")
A16: Pending Demos | B16: =SUMIFS(Variables!M2:M47, Variables!C2:C47,"Mix Services (5-200)") | C16: =SUMIFS(Variables!M2:M47, Variables!C2:C47,"Manufacturing") | D16: =IFERROR(B16/C16,"")
A17: Demos / Emails Sent | B17: =IFERROR((SUMIFS(Variables!K2:K47, Variables!C2:C47,"Mix Services (5-200)"))/(SUMIFS(Variables!F2:F47, Variables!C2:C47,"Mix Services (5-200)")),0) | C17: =IFERROR((SUMIFS(Variables!K2:K47, Variables!C2:C47,"Manufacturing"))/(SUMIFS(Variables!F2:F47, Variables!C2:C47,"Manufacturing")),0) | D17: =IFERROR(B17/C17,"")
A18: Demos / Leads Contacted | B18: =IFERROR((SUMIFS(Variables!K2:K47, Variables!C2:C47,"Mix Services (5-200)"))/(SUMIFS(Variables!G2:G47, Variables!C2:C47,"Mix Services (5-200)")),0) | C18: =IFERROR((SUMIFS(Variables!K2:K47, Variables!C2:C47,"Manufacturing"))/(SUMIFS(Variables!G2:G47, Variables!C2:C47,"Manufacturing")),0) | D18: =IFERROR(B18/C18,"")
A19: Demos / Interested | B19: =IFERROR((SUMIFS(Variables!K2:K47, Variables!C2:C47,"Mix Services (5-200)"))/(SUMIFS(Variables!J2:J47, Variables!C2:C47,"Mix Services (5-200)")),0) | C19: =IFERROR((SUMIFS(Variables!K2:K47, Variables!C2:C47,"Manufacturing"))/(SUMIFS(Variables!J2:J47, Variables!C2:C47,"Manufacturing")),0) | D19: =IFERROR(B19/C19,"")
A20: SHOW-UPS
A21: Total Show-ups | B21: =SUMIFS(Variables!L2:L47, Variables!C2:C47,"Mix Services (5-200)") | C21: =SUMIFS(Variables!L2:L47, Variables!C2:C47,"Manufacturing") | D21: =IFERROR(B21/C21,"")
A22: No-shows | B22: =SUMIFS(Variables!N2:N47, Variables!C2:C47,"Mix Services (5-200)") | C22: =SUMIFS(Variables!N2:N47, Variables!C2:C47,"Manufacturing") | D22: =IFERROR(B22/C22,"")
A23: Show-ups / Emails Sent | B23: =IFERROR((SUMIFS(Variables!L2:L47, Variables!C2:C47,"Mix Services (5-200)"))/(SUMIFS(Variables!F2:F47, Variables!C2:C47,"Mix Services (5-200)")),0) | C23: =IFERROR((SUMIFS(Variables!L2:L47, Variables!C2:C47,"Manufacturing"))/(SUMIFS(Variables!F2:F47, Variables!C2:C47,"Manufacturing")),0) | D23: =IFERROR(B23/C23,"")
A24: Show-ups / Leads Contacted | B24: =IFERROR((SUMIFS(Variables!L2:L47, Variables!C2:C47,"Mix Services (5-200)"))/(SUMIFS(Variables!G2:G47, Variables!C2:C47,"Mix Services (5-200)")),0) | C24: =IFERROR((SUMIFS(Variables!L2:L47, Variables!C2:C47,"Manufacturing"))/(SUMIFS(Variables!G2:G47, Variables!C2:C47,"Manufacturing")),0) | D24: =IFERROR(B24/C24,"")
A25: Show-up Rate (Shows / Completed) | B25: =IFERROR((SUMIFS(Variables!L2:L47, Variables!C2:C47,"Mix Services (5-200)"))/(SUMIFS(Variables!O2:O47, Variables!C2:C47,"Mix Services (5-200)")),0) | C25: =IFERROR((SUMIFS(Variables!L2:L47, Variables!C2:C47,"Manufacturing"))/(SUMIFS(Variables!O2:O47, Variables!C2:C47,"Manufacturing")),0) | D25: =IFERROR(B25/C25,"")
A26: Show-ups / Interested | B26: =IFERROR((SUMIFS(Variables!L2:L47, Variables!C2:C47,"Mix Services (5-200)"))/(SUMIFS(Variables!J2:J47, Variables!C2:C47,"Mix Services (5-200)")),0) | C26: =IFERROR((SUMIFS(Variables!L2:L47, Variables!C2:C47,"Manufacturing"))/(SUMIFS(Variables!J2:J47, Variables!C2:C47,"Manufacturing")),0) | D26: =IFERROR(B26/C26,"")
A27: CLOSED (ONBOARDINGS)
A28: Closed Deals | B28: =SUMIFS(Variables!P2:P47, Variables!C2:C47,"Mix Services (5-200)") | C28: =SUMIFS(Variables!P2:P47, Variables!C2:C47,"Manufacturing") | D28: =IFERROR(B28/C28,"")
A29: ARR | B29: =SUMIFS(Variables!Q2:Q47, Variables!C2:C47,"Mix Services (5-200)") | C29: =SUMIFS(Variables!Q2:Q47, Variables!C2:C47,"Manufacturing") | D29: =IFERROR(B29/C29,"")
A30: MRR | B30: =SUMIFS(Variables!R2:R47, Variables!C2:C47,"Mix Services (5-200)") | C30: =SUMIFS(Variables!R2:R47, Variables!C2:C47,"Manufacturing") | D30: =IFERROR(B30/C30,"")
A31: Close / Demo | B31: =IFERROR((SUMIFS(Variables!P2:P47, Variables!C2:C47,"Mix Services (5-200)"))/(SUMIFS(Variables!K2:K47, Variables!C2:C47,"Mix Services (5-200)")),0) | C31: =IFERROR((SUMIFS(Variables!P2:P47, Variables!C2:C47,"Manufacturing"))/(SUMIFS(Variables!K2:K47, Variables!C2:C47,"Manufacturing")),0) | D31: =IFERROR(B31/C31,"")
A32: Close / Show-up | B32: =IFERROR((SUMIFS(Variables!P2:P47, Variables!C2:C47,"Mix Services (5-200)"))/(SUMIFS(Variables!L2:L47, Variables!C2:C47,"Mix Services (5-200)")),0) | C32: =IFERROR((SUMIFS(Variables!P2:P47, Variables!C2:C47,"Manufacturing"))/(SUMIFS(Variables!L2:L47, Variables!C2:C47,"Manufacturing")),0) | D32: =IFERROR(B32/C32,"")
A33: Close / Interested | B33: =IFERROR((SUMIFS(Variables!P2:P47, Variables!C2:C47,"Mix Services (5-200)"))/(SUMIFS(Variables!J2:J47, Variables!C2:C47,"Mix Services (5-200)")),0) | C33: =IFERROR((SUMIFS(Variables!P2:P47, Variables!C2:C47,"Manufacturing"))/(SUMIFS(Variables!J2:J47, Variables!C2:C47,"Manufacturing")),0) | D33: =IFERROR(B33/C33,"")
A34: Close / Lead | B34: =IFERROR((SUMIFS(Variables!P2:P47, Variables!C2:C47,"Mix Services (5-200)"))/(SUMIFS(Variables!G2:G47, Variables!C2:C47,"Mix Services (5-200)")),0) | C34: =IFERROR((SUMIFS(Variables!P2:P47, Variables!C2:C47,"Manufacturing"))/(SUMIFS(Variables!G2:G47, Variables!C2:C47,"Manufacturing")),0) | D34: =IFERROR(B34/C34,"")

Sheet MFG SE Hook
A1: Industry | B1: Cell ref
A2: MFG SE Hook | B2: used by all formulas below ↓
A4: Metric | B4: MFG SE Hook | C4: Manufacturing (benchmark) | D4: Index vs MFG
A5: EMAIL
A6: Emails Sent | B6: =SUMIFS(Variables!F2:F47, Variables!C2:C47,"MFG SE Hook") | C6: =SUMIFS(Variables!F2:F47, Variables!C2:C47,"Manufacturing") | D6: =IFERROR(B6/C6,"")
A7: Leads Contacted | B7: =SUMIFS(Variables!G2:G47, Variables!C2:C47,"MFG SE Hook") | C7: =SUMIFS(Variables!G2:G47, Variables!C2:C47,"Manufacturing") | D7: =IFERROR(B7/C7,"")
A8: Replied (total) | B8: =SUMIFS(Variables!H2:H47, Variables!C2:C47,"MFG SE Hook") | C8: =SUMIFS(Variables!H2:H47, Variables!C2:C47,"Manufacturing") | D8: =IFERROR(B8/C8,"")
A9: Reply Rate (per lead) | B9: =IFERROR((SUMIFS(Variables!H2:H47, Variables!C2:C47,"MFG SE Hook"))/(SUMIFS(Variables!G2:G47, Variables!C2:C47,"MFG SE Hook")),0) | C9: =IFERROR((SUMIFS(Variables!H2:H47, Variables!C2:C47,"Manufacturing"))/(SUMIFS(Variables!G2:G47, Variables!C2:C47,"Manufacturing")),0) | D9: =IFERROR(B9/C9,"")
A10: Bounced | B10: =SUMIFS(Variables!I2:I47, Variables!C2:C47,"MFG SE Hook") | C10: =SUMIFS(Variables!I2:I47, Variables!C2:C47,"Manufacturing") | D10: =IFERROR(B10/C10,"")
A11: Bounce % (per lead) | B11: =IFERROR((SUMIFS(Variables!I2:I47, Variables!C2:C47,"MFG SE Hook"))/(SUMIFS(Variables!G2:G47, Variables!C2:C47,"MFG SE Hook")),0) | C11: =IFERROR((SUMIFS(Variables!I2:I47, Variables!C2:C47,"Manufacturing"))/(SUMIFS(Variables!G2:G47, Variables!C2:C47,"Manufacturing")),0) | D11: =IFERROR(B11/C11,"")
A12: Interested Replies | B12: =SUMIFS(Variables!J2:J47, Variables!C2:C47,"MFG SE Hook") | C12: =SUMIFS(Variables!J2:J47, Variables!C2:C47,"Manufacturing") | D12: =IFERROR(B12/C12,"")
A13: Interest Rate (per lead) | B13: =IFERROR((SUMIFS(Variables!J2:J47, Variables!C2:C47,"MFG SE Hook"))/(SUMIFS(Variables!G2:G47, Variables!C2:C47,"MFG SE Hook")),0) | C13: =IFERROR((SUMIFS(Variables!J2:J47, Variables!C2:C47,"Manufacturing"))/(SUMIFS(Variables!G2:G47, Variables!C2:C47,"Manufacturing")),0) | D13: =IFERROR(B13/C13,"")
A14: DEMOS
A15: Demos Booked | B15: =SUMIFS(Variables!K2:K47, Variables!C2:C47,"MFG SE Hook") | C15: =SUMIFS(Variables!K2:K47, Variables!C2:C47,"Manufacturing") | D15: =IFERROR(B15/C15,"")
A16: Pending Demos | B16: =SUMIFS(Variables!M2:M47, Variables!C2:C47,"MFG SE Hook") | C16: =SUMIFS(Variables!M2:M47, Variables!C2:C47,"Manufacturing") | D16: =IFERROR(B16/C16,"")
A17: Demos / Emails Sent | B17: =IFERROR((SUMIFS(Variables!K2:K47, Variables!C2:C47,"MFG SE Hook"))/(SUMIFS(Variables!F2:F47, Variables!C2:C47,"MFG SE Hook")),0) | C17: =IFERROR((SUMIFS(Variables!K2:K47, Variables!C2:C47,"Manufacturing"))/(SUMIFS(Variables!F2:F47, Variables!C2:C47,"Manufacturing")),0) | D17: =IFERROR(B17/C17,"")
A18: Demos / Leads Contacted | B18: =IFERROR((SUMIFS(Variables!K2:K47, Variables!C2:C47,"MFG SE Hook"))/(SUMIFS(Variables!G2:G47, Variables!C2:C47,"MFG SE Hook")),0) | C18: =IFERROR((SUMIFS(Variables!K2:K47, Variables!C2:C47,"Manufacturing"))/(SUMIFS(Variables!G2:G47, Variables!C2:C47,"Manufacturing")),0) | D18: =IFERROR(B18/C18,"")
A19: Demos / Interested | B19: =IFERROR((SUMIFS(Variables!K2:K47, Variables!C2:C47,"MFG SE Hook"))/(SUMIFS(Variables!J2:J47, Variables!C2:C47,"MFG SE Hook")),0) | C19: =IFERROR((SUMIFS(Variables!K2:K47, Variables!C2:C47,"Manufacturing"))/(SUMIFS(Variables!J2:J47, Variables!C2:C47,"Manufacturing")),0) | D19: =IFERROR(B19/C19,"")
A20: SHOW-UPS
A21: Total Show-ups | B21: =SUMIFS(Variables!L2:L47, Variables!C2:C47,"MFG SE Hook") | C21: =SUMIFS(Variables!L2:L47, Variables!C2:C47,"Manufacturing") | D21: =IFERROR(B21/C21,"")
A22: No-shows | B22: =SUMIFS(Variables!N2:N47, Variables!C2:C47,"MFG SE Hook") | C22: =SUMIFS(Variables!N2:N47, Variables!C2:C47,"Manufacturing") | D22: =IFERROR(B22/C22,"")
A23: Show-ups / Emails Sent | B23: =IFERROR((SUMIFS(Variables!L2:L47, Variables!C2:C47,"MFG SE Hook"))/(SUMIFS(Variables!F2:F47, Variables!C2:C47,"MFG SE Hook")),0) | C23: =IFERROR((SUMIFS(Variables!L2:L47, Variables!C2:C47,"Manufacturing"))/(SUMIFS(Variables!F2:F47, Variables!C2:C47,"Manufacturing")),0) | D23: =IFERROR(B23/C23,"")
A24: Show-ups / Leads Contacted | B24: =IFERROR((SUMIFS(Variables!L2:L47, Variables!C2:C47,"MFG SE Hook"))/(SUMIFS(Variables!G2:G47, Variables!C2:C47,"MFG SE Hook")),0) | C24: =IFERROR((SUMIFS(Variables!L2:L47, Variables!C2:C47,"Manufacturing"))/(SUMIFS(Variables!G2:G47, Variables!C2:C47,"Manufacturing")),0) | D24: =IFERROR(B24/C24,"")
A25: Show-up Rate (Shows / Completed) | B25: =IFERROR((SUMIFS(Variables!L2:L47, Variables!C2:C47,"MFG SE Hook"))/(SUMIFS(Variables!O2:O47, Variables!C2:C47,"MFG SE Hook")),0) | C25: =IFERROR((SUMIFS(Variables!L2:L47, Variables!C2:C47,"Manufacturing"))/(SUMIFS(Variables!O2:O47, Variables!C2:C47,"Manufacturing")),0) | D25: =IFERROR(B25/C25,"")
A26: Show-ups / Interested | B26: =IFERROR((SUMIFS(Variables!L2:L47, Variables!C2:C47,"MFG SE Hook"))/(SUMIFS(Variables!J2:J47, Variables!C2:C47,"MFG SE Hook")),0) | C26: =IFERROR((SUMIFS(Variables!L2:L47, Variables!C2:C47,"Manufacturing"))/(SUMIFS(Variables!J2:J47, Variables!C2:C47,"Manufacturing")),0) | D26: =IFERROR(B26/C26,"")
A27: CLOSED (ONBOARDINGS)
A28: Closed Deals | B28: =SUMIFS(Variables!P2:P47, Variables!C2:C47,"MFG SE Hook") | C28: =SUMIFS(Variables!P2:P47, Variables!C2:C47,"Manufacturing") | D28: =IFERROR(B28/C28,"")
A29: ARR | B29: =SUMIFS(Variables!Q2:Q47, Variables!C2:C47,"MFG SE Hook") | C29: =SUMIFS(Variables!Q2:Q47, Variables!C2:C47,"Manufacturing") | D29: =IFERROR(B29/C29,"")
A30: MRR | B30: =SUMIFS(Variables!R2:R47, Variables!C2:C47,"MFG SE Hook") | C30: =SUMIFS(Variables!R2:R47, Variables!C2:C47,"Manufacturing") | D30: =IFERROR(B30/C30,"")
A31: Close / Demo | B31: =IFERROR((SUMIFS(Variables!P2:P47, Variables!C2:C47,"MFG SE Hook"))/(SUMIFS(Variables!K2:K47, Variables!C2:C47,"MFG SE Hook")),0) | C31: =IFERROR((SUMIFS(Variables!P2:P47, Variables!C2:C47,"Manufacturing"))/(SUMIFS(Variables!K2:K47, Variables!C2:C47,"Manufacturing")),0) | D31: =IFERROR(B31/C31,"")
A32: Close / Show-up | B32: =IFERROR((SUMIFS(Variables!P2:P47, Variables!C2:C47,"MFG SE Hook"))/(SUMIFS(Variables!L2:L47, Variables!C2:C47,"MFG SE Hook")),0) | C32: =IFERROR((SUMIFS(Variables!P2:P47, Variables!C2:C47,"Manufacturing"))/(SUMIFS(Variables!L2:L47, Variables!C2:C47,"Manufacturing")),0) | D32: =IFERROR(B32/C32,"")
A33: Close / Interested | B33: =IFERROR((SUMIFS(Variables!P2:P47, Variables!C2:C47,"MFG SE Hook"))/(SUMIFS(Variables!J2:J47, Variables!C2:C47,"MFG SE Hook")),0) | C33: =IFERROR((SUMIFS(Variables!P2:P47, Variables!C2:C47,"Manufacturing"))/(SUMIFS(Variables!J2:J47, Variables!C2:C47,"Manufacturing")),0) | D33: =IFERROR(B33/C33,"")
A34: Close / Lead | B34: =IFERROR((SUMIFS(Variables!P2:P47, Variables!C2:C47,"MFG SE Hook"))/(SUMIFS(Variables!G2:G47, Variables!C2:C47,"MFG SE Hook")),0) | C34: =IFERROR((SUMIFS(Variables!P2:P47, Variables!C2:C47,"Manufacturing"))/(SUMIFS(Variables!G2:G47, Variables!C2:C47,"Manufacturing")),0) | D34: =IFERROR(B34/C34,"")

Sheet MFG Account
A1: Industry | B1: Cell ref
A2: MFG Account | B2: used by all formulas below ↓
A4: Metric | B4: MFG Account | C4: Manufacturing (benchmark) | D4: Index vs MFG
A5: EMAIL
A6: Emails Sent | B6: =SUMIFS(Variables!F2:F47, Variables!C2:C47,"MFG Account") | C6: =SUMIFS(Variables!F2:F47, Variables!C2:C47,"Manufacturing") | D6: =IFERROR(B6/C6,"")
A7: Leads Contacted | B7: =SUMIFS(Variables!G2:G47, Variables!C2:C47,"MFG Account") | C7: =SUMIFS(Variables!G2:G47, Variables!C2:C47,"Manufacturing") | D7: =IFERROR(B7/C7,"")
A8: Replied (total) | B8: =SUMIFS(Variables!H2:H47, Variables!C2:C47,"MFG Account") | C8: =SUMIFS(Variables!H2:H47, Variables!C2:C47,"Manufacturing") | D8: =IFERROR(B8/C8,"")
A9: Reply Rate (per lead) | B9: =IFERROR((SUMIFS(Variables!H2:H47, Variables!C2:C47,"MFG Account"))/(SUMIFS(Variables!G2:G47, Variables!C2:C47,"MFG Account")),0) | C9: =IFERROR((SUMIFS(Variables!H2:H47, Variables!C2:C47,"Manufacturing"))/(SUMIFS(Variables!G2:G47, Variables!C2:C47,"Manufacturing")),0) | D9: =IFERROR(B9/C9,"")
A10: Bounced | B10: =SUMIFS(Variables!I2:I47, Variables!C2:C47,"MFG Account") | C10: =SUMIFS(Variables!I2:I47, Variables!C2:C47,"Manufacturing") | D10: =IFERROR(B10/C10,"")
A11: Bounce % (per lead) | B11: =IFERROR((SUMIFS(Variables!I2:I47, Variables!C2:C47,"MFG Account"))/(SUMIFS(Variables!G2:G47, Variables!C2:C47,"MFG Account")),0) | C11: =IFERROR((SUMIFS(Variables!I2:I47, Variables!C2:C47,"Manufacturing"))/(SUMIFS(Variables!G2:G47, Variables!C2:C47,"Manufacturing")),0) | D11: =IFERROR(B11/C11,"")
A12: Interested Replies | B12: =SUMIFS(Variables!J2:J47, Variables!C2:C47,"MFG Account") | C12: =SUMIFS(Variables!J2:J47, Variables!C2:C47,"Manufacturing") | D12: =IFERROR(B12/C12,"")
A13: Interest Rate (per lead) | B13: =IFERROR((SUMIFS(Variables!J2:J47, Variables!C2:C47,"MFG Account"))/(SUMIFS(Variables!G2:G47, Variables!C2:C47,"MFG Account")),0) | C13: =IFERROR((SUMIFS(Variables!J2:J47, Variables!C2:C47,"Manufacturing"))/(SUMIFS(Variables!G2:G47, Variables!C2:C47,"Manufacturing")),0) | D13: =IFERROR(B13/C13,"")
A14: DEMOS
A15: Demos Booked | B15: =SUMIFS(Variables!K2:K47, Variables!C2:C47,"MFG Account") | C15: =SUMIFS(Variables!K2:K47, Variables!C2:C47,"Manufacturing") | D15: =IFERROR(B15/C15,"")
A16: Pending Demos | B16: =SUMIFS(Variables!M2:M47, Variables!C2:C47,"MFG Account") | C16: =SUMIFS(Variables!M2:M47, Variables!C2:C47,"Manufacturing") | D16: =IFERROR(B16/C16,"")
A17: Demos / Emails Sent | B17: =IFERROR((SUMIFS(Variables!K2:K47, Variables!C2:C47,"MFG Account"))/(SUMIFS(Variables!F2:F47, Variables!C2:C47,"MFG Account")),0) | C17: =IFERROR((SUMIFS(Variables!K2:K47, Variables!C2:C47,"Manufacturing"))/(SUMIFS(Variables!F2:F47, Variables!C2:C47,"Manufacturing")),0) | D17: =IFERROR(B17/C17,"")
A18: Demos / Leads Contacted | B18: =IFERROR((SUMIFS(Variables!K2:K47, Variables!C2:C47,"MFG Account"))/(SUMIFS(Variables!G2:G47, Variables!C2:C47,"MFG Account")),0) | C18: =IFERROR((SUMIFS(Variables!K2:K47, Variables!C2:C47,"Manufacturing"))/(SUMIFS(Variables!G2:G47, Variables!C2:C47,"Manufacturing")),0) | D18: =IFERROR(B18/C18,"")
A19: Demos / Interested | B19: =IFERROR((SUMIFS(Variables!K2:K47, Variables!C2:C47,"MFG Account"))/(SUMIFS(Variables!J2:J47, Variables!C2:C47,"MFG Account")),0) | C19: =IFERROR((SUMIFS(Variables!K2:K47, Variables!C2:C47,"Manufacturing"))/(SUMIFS(Variables!J2:J47, Variables!C2:C47,"Manufacturing")),0) | D19: =IFERROR(B19/C19,"")
A20: SHOW-UPS
A21: Total Show-ups | B21: =SUMIFS(Variables!L2:L47, Variables!C2:C47,"MFG Account") | C21: =SUMIFS(Variables!L2:L47, Variables!C2:C47,"Manufacturing") | D21: =IFERROR(B21/C21,"")
A22: No-shows | B22: =SUMIFS(Variables!N2:N47, Variables!C2:C47,"MFG Account") | C22: =SUMIFS(Variables!N2:N47, Variables!C2:C47,"Manufacturing") | D22: =IFERROR(B22/C22,"")
A23: Show-ups / Emails Sent | B23: =IFERROR((SUMIFS(Variables!L2:L47, Variables!C2:C47,"MFG Account"))/(SUMIFS(Variables!F2:F47, Variables!C2:C47,"MFG Account")),0) | C23: =IFERROR((SUMIFS(Variables!L2:L47, Variables!C2:C47,"Manufacturing"))/(SUMIFS(Variables!F2:F47, Variables!C2:C47,"Manufacturing")),0) | D23: =IFERROR(B23/C23,"")
A24: Show-ups / Leads Contacted | B24: =IFERROR((SUMIFS(Variables!L2:L47, Variables!C2:C47,"MFG Account"))/(SUMIFS(Variables!G2:G47, Variables!C2:C47,"MFG Account")),0) | C24: =IFERROR((SUMIFS(Variables!L2:L47, Variables!C2:C47,"Manufacturing"))/(SUMIFS(Variables!G2:G47, Variables!C2:C47,"Manufacturing")),0) | D24: =IFERROR(B24/C24,"")
A25: Show-up Rate (Shows / Completed) | B25: =IFERROR((SUMIFS(Variables!L2:L47, Variables!C2:C47,"MFG Account"))/(SUMIFS(Variables!O2:O47, Variables!C2:C47,"MFG Account")),0) | C25: =IFERROR((SUMIFS(Variables!L2:L47, Variables!C2:C47,"Manufacturing"))/(SUMIFS(Variables!O2:O47, Variables!C2:C47,"Manufacturing")),0) | D25: =IFERROR(B25/C25,"")
A26: Show-ups / Interested | B26: =IFERROR((SUMIFS(Variables!L2:L47, Variables!C2:C47,"MFG Account"))/(SUMIFS(Variables!J2:J47, Variables!C2:C47,"MFG Account")),0) | C26: =IFERROR((SUMIFS(Variables!L2:L47, Variables!C2:C47,"Manufacturing"))/(SUMIFS(Variables!J2:J47, Variables!C2:C47,"Manufacturing")),0) | D26: =IFERROR(B26/C26,"")
A27: CLOSED (ONBOARDINGS)
A28: Closed Deals | B28: =SUMIFS(Variables!P2:P47, Variables!C2:C47,"MFG Account") | C28: =SUMIFS(Variables!P2:P47, Variables!C2:C47,"Manufacturing") | D28: =IFERROR(B28/C28,"")
A29: ARR | B29: =SUMIFS(Variables!Q2:Q47, Variables!C2:C47,"MFG Account") | C29: =SUMIFS(Variables!Q2:Q47, Variables!C2:C47,"Manufacturing") | D29: =IFERROR(B29/C29,"")
A30: MRR | B30: =SUMIFS(Variables!R2:R47, Variables!C2:C47,"MFG Account") | C30: =SUMIFS(Variables!R2:R47, Variables!C2:C47,"Manufacturing") | D30: =IFERROR(B30/C30,"")
A31: Close / Demo | B31: =IFERROR((SUMIFS(Variables!P2:P47, Variables!C2:C47,"MFG Account"))/(SUMIFS(Variables!K2:K47, Variables!C2:C47,"MFG Account")),0) | C31: =IFERROR((SUMIFS(Variables!P2:P47, Variables!C2:C47,"Manufacturing"))/(SUMIFS(Variables!K2:K47, Variables!C2:C47,"Manufacturing")),0) | D31: =IFERROR(B31/C31,"")
A32: Close / Show-up | B32: =IFERROR((SUMIFS(Variables!P2:P47, Variables!C2:C47,"MFG Account"))/(SUMIFS(Variables!L2:L47, Variables!C2:C47,"MFG Account")),0) | C32: =IFERROR((SUMIFS(Variables!P2:P47, Variables!C2:C47,"Manufacturing"))/(SUMIFS(Variables!L2:L47, Variables!C2:C47,"Manufacturing")),0) | D32: =IFERROR(B32/C32,"")
A33: Close / Interested | B33: =IFERROR((SUMIFS(Variables!P2:P47, Variables!C2:C47,"MFG Account"))/(SUMIFS(Variables!J2:J47, Variables!C2:C47,"MFG Account")),0) | C33: =IFERROR((SUMIFS(Variables!P2:P47, Variables!C2:C47,"Manufacturing"))/(SUMIFS(Variables!J2:J47, Variables!C2:C47,"Manufacturing")),0) | D33: =IFERROR(B33/C33,"")
A34: Close / Lead | B34: =IFERROR((SUMIFS(Variables!P2:P47, Variables!C2:C47,"MFG Account"))/(SUMIFS(Variables!G2:G47, Variables!C2:C47,"MFG Account")),0) | C34: =IFERROR((SUMIFS(Variables!P2:P47, Variables!C2:C47,"Manufacturing"))/(SUMIFS(Variables!G2:G47, Variables!C2:C47,"Manufacturing")),0) | D34: =IFERROR(B34/C34,"")

Sheet Corporate Training
A1: Industry | B1: Cell ref
A2: Corporate Training | B2: used by all formulas below ↓
A4: Metric | B4: Corporate Training | C4: Manufacturing (benchmark) | D4: Index vs MFG
A5: EMAIL
A6: Emails Sent | B6: =SUMIFS(Variables!F2:F47, Variables!C2:C47,"Corporate Training") | C6: =SUMIFS(Variables!F2:F47, Variables!C2:C47,"Manufacturing") | D6: =IFERROR(B6/C6,"")
A7: Leads Contacted | B7: =SUMIFS(Variables!G2:G47, Variables!C2:C47,"Corporate Training") | C7: =SUMIFS(Variables!G2:G47, Variables!C2:C47,"Manufacturing") | D7: =IFERROR(B7/C7,"")
A8: Replied (total) | B8: =SUMIFS(Variables!H2:H47, Variables!C2:C47,"Corporate Training") | C8: =SUMIFS(Variables!H2:H47, Variables!C2:C47,"Manufacturing") | D8: =IFERROR(B8/C8,"")
A9: Reply Rate (per lead) | B9: =IFERROR((SUMIFS(Variables!H2:H47, Variables!C2:C47,"Corporate Training"))/(SUMIFS(Variables!G2:G47, Variables!C2:C47,"Corporate Training")),0) | C9: =IFERROR((SUMIFS(Variables!H2:H47, Variables!C2:C47,"Manufacturing"))/(SUMIFS(Variables!G2:G47, Variables!C2:C47,"Manufacturing")),0) | D9: =IFERROR(B9/C9,"")
A10: Bounced | B10: =SUMIFS(Variables!I2:I47, Variables!C2:C47,"Corporate Training") | C10: =SUMIFS(Variables!I2:I47, Variables!C2:C47,"Manufacturing") | D10: =IFERROR(B10/C10,"")
A11: Bounce % (per lead) | B11: =IFERROR((SUMIFS(Variables!I2:I47, Variables!C2:C47,"Corporate Training"))/(SUMIFS(Variables!G2:G47, Variables!C2:C47,"Corporate Training")),0) | C11: =IFERROR((SUMIFS(Variables!I2:I47, Variables!C2:C47,"Manufacturing"))/(SUMIFS(Variables!G2:G47, Variables!C2:C47,"Manufacturing")),0) | D11: =IFERROR(B11/C11,"")
A12: Interested Replies | B12: =SUMIFS(Variables!J2:J47, Variables!C2:C47,"Corporate Training") | C12: =SUMIFS(Variables!J2:J47, Variables!C2:C47,"Manufacturing") | D12: =IFERROR(B12/C12,"")
A13: Interest Rate (per lead) | B13: =IFERROR((SUMIFS(Variables!J2:J47, Variables!C2:C47,"Corporate Training"))/(SUMIFS(Variables!G2:G47, Variables!C2:C47,"Corporate Training")),0) | C13: =IFERROR((SUMIFS(Variables!J2:J47, Variables!C2:C47,"Manufacturing"))/(SUMIFS(Variables!G2:G47, Variables!C2:C47,"Manufacturing")),0) | D13: =IFERROR(B13/C13,"")
A14: DEMOS
A15: Demos Booked | B15: =SUMIFS(Variables!K2:K47, Variables!C2:C47,"Corporate Training") | C15: =SUMIFS(Variables!K2:K47, Variables!C2:C47,"Manufacturing") | D15: =IFERROR(B15/C15,"")
A16: Pending Demos | B16: =SUMIFS(Variables!M2:M47, Variables!C2:C47,"Corporate Training") | C16: =SUMIFS(Variables!M2:M47, Variables!C2:C47,"Manufacturing") | D16: =IFERROR(B16/C16,"")
A17: Demos / Emails Sent | B17: =IFERROR((SUMIFS(Variables!K2:K47, Variables!C2:C47,"Corporate Training"))/(SUMIFS(Variables!F2:F47, Variables!C2:C47,"Corporate Training")),0) | C17: =IFERROR((SUMIFS(Variables!K2:K47, Variables!C2:C47,"Manufacturing"))/(SUMIFS(Variables!F2:F47, Variables!C2:C47,"Manufacturing")),0) | D17: =IFERROR(B17/C17,"")
A18: Demos / Leads Contacted | B18: =IFERROR((SUMIFS(Variables!K2:K47, Variables!C2:C47,"Corporate Training"))/(SUMIFS(Variables!G2:G47, Variables!C2:C47,"Corporate Training")),0) | C18: =IFERROR((SUMIFS(Variables!K2:K47, Variables!C2:C47,"Manufacturing"))/(SUMIFS(Variables!G2:G47, Variables!C2:C47,"Manufacturing")),0) | D18: =IFERROR(B18/C18,"")
A19: Demos / Interested | B19: =IFERROR((SUMIFS(Variables!K2:K47, Variables!C2:C47,"Corporate Training"))/(SUMIFS(Variables!J2:J47, Variables!C2:C47,"Corporate Training")),0) | C19: =IFERROR((SUMIFS(Variables!K2:K47, Variables!C2:C47,"Manufacturing"))/(SUMIFS(Variables!J2:J47, Variables!C2:C47,"Manufacturing")),0) | D19: =IFERROR(B19/C19,"")
A20: SHOW-UPS
A21: Total Show-ups | B21: =SUMIFS(Variables!L2:L47, Variables!C2:C47,"Corporate Training") | C21: =SUMIFS(Variables!L2:L47, Variables!C2:C47,"Manufacturing") | D21: =IFERROR(B21/C21,"")
A22: No-shows | B22: =SUMIFS(Variables!N2:N47, Variables!C2:C47,"Corporate Training") | C22: =SUMIFS(Variables!N2:N47, Variables!C2:C47,"Manufacturing") | D22: =IFERROR(B22/C22,"")
A23: Show-ups / Emails Sent | B23: =IFERROR((SUMIFS(Variables!L2:L47, Variables!C2:C47,"Corporate Training"))/(SUMIFS(Variables!F2:F47, Variables!C2:C47,"Corporate Training")),0) | C23: =IFERROR((SUMIFS(Variables!L2:L47, Variables!C2:C47,"Manufacturing"))/(SUMIFS(Variables!F2:F47, Variables!C2:C47,"Manufacturing")),0) | D23: =IFERROR(B23/C23,"")
A24: Show-ups / Leads Contacted | B24: =IFERROR((SUMIFS(Variables!L2:L47, Variables!C2:C47,"Corporate Training"))/(SUMIFS(Variables!G2:G47, Variables!C2:C47,"Corporate Training")),0) | C24: =IFERROR((SUMIFS(Variables!L2:L47, Variables!C2:C47,"Manufacturing"))/(SUMIFS(Variables!G2:G47, Variables!C2:C47,"Manufacturing")),0) | D24: =IFERROR(B24/C24,"")
A25: Show-up Rate (Shows / Completed) | B25: =IFERROR((SUMIFS(Variables!L2:L47, Variables!C2:C47,"Corporate Training"))/(SUMIFS(Variables!O2:O47, Variables!C2:C47,"Corporate Training")),0) | C25: =IFERROR((SUMIFS(Variables!L2:L47, Variables!C2:C47,"Manufacturing"))/(SUMIFS(Variables!O2:O47, Variables!C2:C47,"Manufacturing")),0) | D25: =IFERROR(B25/C25,"")
A26: Show-ups / Interested | B26: =IFERROR((SUMIFS(Variables!L2:L47, Variables!C2:C47,"Corporate Training"))/(SUMIFS(Variables!J2:J47, Variables!C2:C47,"Corporate Training")),0) | C26: =IFERROR((SUMIFS(Variables!L2:L47, Variables!C2:C47,"Manufacturing"))/(SUMIFS(Variables!J2:J47, Variables!C2:C47,"Manufacturing")),0) | D26: =IFERROR(B26/C26,"")
A27: CLOSED (ONBOARDINGS)
A28: Closed Deals | B28: =SUMIFS(Variables!P2:P47, Variables!C2:C47,"Corporate Training") | C28: =SUMIFS(Variables!P2:P47, Variables!C2:C47,"Manufacturing") | D28: =IFERROR(B28/C28,"")
A29: ARR | B29: =SUMIFS(Variables!Q2:Q47, Variables!C2:C47,"Corporate Training") | C29: =SUMIFS(Variables!Q2:Q47, Variables!C2:C47,"Manufacturing") | D29: =IFERROR(B29/C29,"")
A30: MRR | B30: =SUMIFS(Variables!R2:R47, Variables!C2:C47,"Corporate Training") | C30: =SUMIFS(Variables!R2:R47, Variables!C2:C47,"Manufacturing") | D30: =IFERROR(B30/C30,"")
A31: Close / Demo | B31: =IFERROR((SUMIFS(Variables!P2:P47, Variables!C2:C47,"Corporate Training"))/(SUMIFS(Variables!K2:K47, Variables!C2:C47,"Corporate Training")),0) | C31: =IFERROR((SUMIFS(Variables!P2:P47, Variables!C2:C47,"Manufacturing"))/(SUMIFS(Variables!K2:K47, Variables!C2:C47,"Manufacturing")),0) | D31: =IFERROR(B31/C31,"")
A32: Close / Show-up | B32: =IFERROR((SUMIFS(Variables!P2:P47, Variables!C2:C47,"Corporate Training"))/(SUMIFS(Variables!L2:L47, Variables!C2:C47,"Corporate Training")),0) | C32: =IFERROR((SUMIFS(Variables!P2:P47, Variables!C2:C47,"Manufacturing"))/(SUMIFS(Variables!L2:L47, Variables!C2:C47,"Manufacturing")),0) | D32: =IFERROR(B32/C32,"")
A33: Close / Interested | B33: =IFERROR((SUMIFS(Variables!P2:P47, Variables!C2:C47,"Corporate Training"))/(SUMIFS(Variables!J2:J47, Variables!C2:C47,"Corporate Training")),0) | C33: =IFERROR((SUMIFS(Variables!P2:P47, Variables!C2:C47,"Manufacturing"))/(SUMIFS(Variables!J2:J47, Variables!C2:C47,"Manufacturing")),0) | D33: =IFERROR(B33/C33,"")
A34: Close / Lead | B34: =IFERROR((SUMIFS(Variables!P2:P47, Variables!C2:C47,"Corporate Training"))/(SUMIFS(Variables!G2:G47, Variables!C2:C47,"Corporate Training")),0) | C34: =IFERROR((SUMIFS(Variables!P2:P47, Variables!C2:C47,"Manufacturing"))/(SUMIFS(Variables!G2:G47, Variables!C2:C47,"Manufacturing")),0) | D34: =IFERROR(B34/C34,"")

Sheet MFG 1-5
A1: Industry | B1: Cell ref
A2: MFG 1-5 | B2: used by all formulas below ↓
A4: Metric | B4: MFG 1-5 | C4: Manufacturing (benchmark) | D4: Index vs MFG
A5: EMAIL
A6: Emails Sent | B6: =SUMIFS(Variables!F2:F47, Variables!C2:C47,"MFG 1-5") | C6: =SUMIFS(Variables!F2:F47, Variables!C2:C47,"Manufacturing") | D6: =IFERROR(B6/C6,"")
A7: Leads Contacted | B7: =SUMIFS(Variables!G2:G47, Variables!C2:C47,"MFG 1-5") | C7: =SUMIFS(Variables!G2:G47, Variables!C2:C47,"Manufacturing") | D7: =IFERROR(B7/C7,"")
A8: Replied (total) | B8: =SUMIFS(Variables!H2:H47, Variables!C2:C47,"MFG 1-5") | C8: =SUMIFS(Variables!H2:H47, Variables!C2:C47,"Manufacturing") | D8: =IFERROR(B8/C8,"")
A9: Reply Rate (per lead) | B9: =IFERROR((SUMIFS(Variables!H2:H47, Variables!C2:C47,"MFG 1-5"))/(SUMIFS(Variables!G2:G47, Variables!C2:C47,"MFG 1-5")),0) | C9: =IFERROR((SUMIFS(Variables!H2:H47, Variables!C2:C47,"Manufacturing"))/(SUMIFS(Variables!G2:G47, Variables!C2:C47,"Manufacturing")),0) | D9: =IFERROR(B9/C9,"")
A10: Bounced | B10: =SUMIFS(Variables!I2:I47, Variables!C2:C47,"MFG 1-5") | C10: =SUMIFS(Variables!I2:I47, Variables!C2:C47,"Manufacturing") | D10: =IFERROR(B10/C10,"")
A11: Bounce % (per lead) | B11: =IFERROR((SUMIFS(Variables!I2:I47, Variables!C2:C47,"MFG 1-5"))/(SUMIFS(Variables!G2:G47, Variables!C2:C47,"MFG 1-5")),0) | C11: =IFERROR((SUMIFS(Variables!I2:I47, Variables!C2:C47,"Manufacturing"))/(SUMIFS(Variables!G2:G47, Variables!C2:C47,"Manufacturing")),0) | D11: =IFERROR(B11/C11,"")
A12: Interested Replies | B12: =SUMIFS(Variables!J2:J47, Variables!C2:C47,"MFG 1-5") | C12: =SUMIFS(Variables!J2:J47, Variables!C2:C47,"Manufacturing") | D12: =IFERROR(B12/C12,"")
A13: Interest Rate (per lead) | B13: =IFERROR((SUMIFS(Variables!J2:J47, Variables!C2:C47,"MFG 1-5"))/(SUMIFS(Variables!G2:G47, Variables!C2:C47,"MFG 1-5")),0) | C13: =IFERROR((SUMIFS(Variables!J2:J47, Variables!C2:C47,"Manufacturing"))/(SUMIFS(Variables!G2:G47, Variables!C2:C47,"Manufacturing")),0) | D13: =IFERROR(B13/C13,"")
A14: DEMOS
A15: Demos Booked | B15: =SUMIFS(Variables!K2:K47, Variables!C2:C47,"MFG 1-5") | C15: =SUMIFS(Variables!K2:K47, Variables!C2:C47,"Manufacturing") | D15: =IFERROR(B15/C15,"")
A16: Pending Demos | B16: =SUMIFS(Variables!M2:M47, Variables!C2:C47,"MFG 1-5") | C16: =SUMIFS(Variables!M2:M47, Variables!C2:C47,"Manufacturing") | D16: =IFERROR(B16/C16,"")
A17: Demos / Emails Sent | B17: =IFERROR((SUMIFS(Variables!K2:K47, Variables!C2:C47,"MFG 1-5"))/(SUMIFS(Variables!F2:F47, Variables!C2:C47,"MFG 1-5")),0) | C17: =IFERROR((SUMIFS(Variables!K2:K47, Variables!C2:C47,"Manufacturing"))/(SUMIFS(Variables!F2:F47, Variables!C2:C47,"Manufacturing")),0) | D17: =IFERROR(B17/C17,"")
A18: Demos / Leads Contacted | B18: =IFERROR((SUMIFS(Variables!K2:K47, Variables!C2:C47,"MFG 1-5"))/(SUMIFS(Variables!G2:G47, Variables!C2:C47,"MFG 1-5")),0) | C18: =IFERROR((SUMIFS(Variables!K2:K47, Variables!C2:C47,"Manufacturing"))/(SUMIFS(Variables!G2:G47, Variables!C2:C47,"Manufacturing")),0) | D18: =IFERROR(B18/C18,"")
A19: Demos / Interested | B19: =IFERROR((SUMIFS(Variables!K2:K47, Variables!C2:C47,"MFG 1-5"))/(SUMIFS(Variables!J2:J47, Variables!C2:C47,"MFG 1-5")),0) | C19: =IFERROR((SUMIFS(Variables!K2:K47, Variables!C2:C47,"Manufacturing"))/(SUMIFS(Variables!J2:J47, Variables!C2:C47,"Manufacturing")),0) | D19: =IFERROR(B19/C19,"")
A20: SHOW-UPS
A21: Total Show-ups | B21: =SUMIFS(Variables!L2:L47, Variables!C2:C47,"MFG 1-5") | C21: =SUMIFS(Variables!L2:L47, Variables!C2:C47,"Manufacturing") | D21: =IFERROR(B21/C21,"")
A22: No-shows | B22: =SUMIFS(Variables!N2:N47, Variables!C2:C47,"MFG 1-5") | C22: =SUMIFS(Variables!N2:N47, Variables!C2:C47,"Manufacturing") | D22: =IFERROR(B22/C22,"")
A23: Show-ups / Emails Sent | B23: =IFERROR((SUMIFS(Variables!L2:L47, Variables!C2:C47,"MFG 1-5"))/(SUMIFS(Variables!F2:F47, Variables!C2:C47,"MFG 1-5")),0) | C23: =IFERROR((SUMIFS(Variables!L2:L47, Variables!C2:C47,"Manufacturing"))/(SUMIFS(Variables!F2:F47, Variables!C2:C47,"Manufacturing")),0) | D23: =IFERROR(B23/C23,"")
A24: Show-ups / Leads Contacted | B24: =IFERROR((SUMIFS(Variables!L2:L47, Variables!C2:C47,"MFG 1-5"))/(SUMIFS(Variables!G2:G47, Variables!C2:C47,"MFG 1-5")),0) | C24: =IFERROR((SUMIFS(Variables!L2:L47, Variables!C2:C47,"Manufacturing"))/(SUMIFS(Variables!G2:G47, Variables!C2:C47,"Manufacturing")),0) | D24: =IFERROR(B24/C24,"")
A25: Show-up Rate (Shows / Completed) | B25: =IFERROR((SUMIFS(Variables!L2:L47, Variables!C2:C47,"MFG 1-5"))/(SUMIFS(Variables!O2:O47, Variables!C2:C47,"MFG 1-5")),0) | C25: =IFERROR((SUMIFS(Variables!L2:L47, Variables!C2:C47,"Manufacturing"))/(SUMIFS(Variables!O2:O47, Variables!C2:C47,"Manufacturing")),0) | D25: =IFERROR(B25/C25,"")
A26: Show-ups / Interested | B26: =IFERROR((SUMIFS(Variables!L2:L47, Variables!C2:C47,"MFG 1-5"))/(SUMIFS(Variables!J2:J47, Variables!C2:C47,"MFG 1-5")),0) | C26: =IFERROR((SUMIFS(Variables!L2:L47, Variables!C2:C47,"Manufacturing"))/(SUMIFS(Variables!J2:J47, Variables!C2:C47,"Manufacturing")),0) | D26: =IFERROR(B26/C26,"")
A27: CLOSED (ONBOARDINGS)
A28: Closed Deals | B28: =SUMIFS(Variables!P2:P47, Variables!C2:C47,"MFG 1-5") | C28: =SUMIFS(Variables!P2:P47, Variables!C2:C47,"Manufacturing") | D28: =IFERROR(B28/C28,"")
A29: ARR | B29: =SUMIFS(Variables!Q2:Q47, Variables!C2:C47,"MFG 1-5") | C29: =SUMIFS(Variables!Q2:Q47, Variables!C2:C47,"Manufacturing") | D29: =IFERROR(B29/C29,"")
A30: MRR | B30: =SUMIFS(Variables!R2:R47, Variables!C2:C47,"MFG 1-5") | C30: =SUMIFS(Variables!R2:R47, Variables!C2:C47,"Manufacturing") | D30: =IFERROR(B30/C30,"")
A31: Close / Demo | B31: =IFERROR((SUMIFS(Variables!P2:P47, Variables!C2:C47,"MFG 1-5"))/(SUMIFS(Variables!K2:K47, Variables!C2:C47,"MFG 1-5")),0) | C31: =IFERROR((SUMIFS(Variables!P2:P47, Variables!C2:C47,"Manufacturing"))/(SUMIFS(Variables!K2:K47, Variables!C2:C47,"Manufacturing")),0) | D31: =IFERROR(B31/C31,"")
A32: Close / Show-up | B32: =IFERROR((SUMIFS(Variables!P2:P47, Variables!C2:C47,"MFG 1-5"))/(SUMIFS(Variables!L2:L47, Variables!C2:C47,"MFG 1-5")),0) | C32: =IFERROR((SUMIFS(Variables!P2:P47, Variables!C2:C47,"Manufacturing"))/(SUMIFS(Variables!L2:L47, Variables!C2:C47,"Manufacturing")),0) | D32: =IFERROR(B32/C32,"")
A33: Close / Interested | B33: =IFERROR((SUMIFS(Variables!P2:P47, Variables!C2:C47,"MFG 1-5"))/(SUMIFS(Variables!J2:J47, Variables!C2:C47,"MFG 1-5")),0) | C33: =IFERROR((SUMIFS(Variables!P2:P47, Variables!C2:C47,"Manufacturing"))/(SUMIFS(Variables!J2:J47, Variables!C2:C47,"Manufacturing")),0) | D33: =IFERROR(B33/C33,"")
A34: Close / Lead | B34: =IFERROR((SUMIFS(Variables!P2:P47, Variables!C2:C47,"MFG 1-5"))/(SUMIFS(Variables!G2:G47, Variables!C2:C47,"MFG 1-5")),0) | C34: =IFERROR((SUMIFS(Variables!P2:P47, Variables!C2:C47,"Manufacturing"))/(SUMIFS(Variables!G2:G47, Variables!C2:C47,"Manufacturing")),0) | D34: =IFERROR(B34/C34,"")

Sheet Financial Services 1-5
A1: Industry | B1: Cell ref
A2: Financial Services 1-5 | B2: used by all formulas below ↓
A4: Metric | B4: Financial Services 1-5 | C4: Manufacturing (benchmark) | D4: Index vs MFG
A5: EMAIL
A6: Emails Sent | B6: =SUMIFS(Variables!F2:F47, Variables!C2:C47,"Financial Services 1-5") | C6: =SUMIFS(Variables!F2:F47, Variables!C2:C47,"Manufacturing") | D6: =IFERROR(B6/C6,"")
A7: Leads Contacted | B7: =SUMIFS(Variables!G2:G47, Variables!C2:C47,"Financial Services 1-5") | C7: =SUMIFS(Variables!G2:G47, Variables!C2:C47,"Manufacturing") | D7: =IFERROR(B7/C7,"")
A8: Replied (total) | B8: =SUMIFS(Variables!H2:H47, Variables!C2:C47,"Financial Services 1-5") | C8: =SUMIFS(Variables!H2:H47, Variables!C2:C47,"Manufacturing") | D8: =IFERROR(B8/C8,"")
A9: Reply Rate (per lead) | B9: =IFERROR((SUMIFS(Variables!H2:H47, Variables!C2:C47,"Financial Services 1-5"))/(SUMIFS(Variables!G2:G47, Variables!C2:C47,"Financial Services 1-5")),0) | C9: =IFERROR((SUMIFS(Variables!H2:H47, Variables!C2:C47,"Manufacturing"))/(SUMIFS(Variables!G2:G47, Variables!C2:C47,"Manufacturing")),0) | D9: =IFERROR(B9/C9,"")
A10: Bounced | B10: =SUMIFS(Variables!I2:I47, Variables!C2:C47,"Financial Services 1-5") | C10: =SUMIFS(Variables!I2:I47, Variables!C2:C47,"Manufacturing") | D10: =IFERROR(B10/C10,"")
A11: Bounce % (per lead) | B11: =IFERROR((SUMIFS(Variables!I2:I47, Variables!C2:C47,"Financial Services 1-5"))/(SUMIFS(Variables!G2:G47, Variables!C2:C47,"Financial Services 1-5")),0) | C11: =IFERROR((SUMIFS(Variables!I2:I47, Variables!C2:C47,"Manufacturing"))/(SUMIFS(Variables!G2:G47, Variables!C2:C47,"Manufacturing")),0) | D11: =IFERROR(B11/C11,"")
A12: Interested Replies | B12: =SUMIFS(Variables!J2:J47, Variables!C2:C47,"Financial Services 1-5") | C12: =SUMIFS(Variables!J2:J47, Variables!C2:C47,"Manufacturing") | D12: =IFERROR(B12/C12,"")
A13: Interest Rate (per lead) | B13: =IFERROR((SUMIFS(Variables!J2:J47, Variables!C2:C47,"Financial Services 1-5"))/(SUMIFS(Variables!G2:G47, Variables!C2:C47,"Financial Services 1-5")),0) | C13: =IFERROR((SUMIFS(Variables!J2:J47, Variables!C2:C47,"Manufacturing"))/(SUMIFS(Variables!G2:G47, Variables!C2:C47,"Manufacturing")),0) | D13: =IFERROR(B13/C13,"")
A14: DEMOS
A15: Demos Booked | B15: =SUMIFS(Variables!K2:K47, Variables!C2:C47,"Financial Services 1-5") | C15: =SUMIFS(Variables!K2:K47, Variables!C2:C47,"Manufacturing") | D15: =IFERROR(B15/C15,"")
A16: Pending Demos | B16: =SUMIFS(Variables!M2:M47, Variables!C2:C47,"Financial Services 1-5") | C16: =SUMIFS(Variables!M2:M47, Variables!C2:C47,"Manufacturing") | D16: =IFERROR(B16/C16,"")
A17: Demos / Emails Sent | B17: =IFERROR((SUMIFS(Variables!K2:K47, Variables!C2:C47,"Financial Services 1-5"))/(SUMIFS(Variables!F2:F47, Variables!C2:C47,"Financial Services 1-5")),0) | C17: =IFERROR((SUMIFS(Variables!K2:K47, Variables!C2:C47,"Manufacturing"))/(SUMIFS(Variables!F2:F47, Variables!C2:C47,"Manufacturing")),0) | D17: =IFERROR(B17/C17,"")
A18: Demos / Leads Contacted | B18: =IFERROR((SUMIFS(Variables!K2:K47, Variables!C2:C47,"Financial Services 1-5"))/(SUMIFS(Variables!G2:G47, Variables!C2:C47,"Financial Services 1-5")),0) | C18: =IFERROR((SUMIFS(Variables!K2:K47, Variables!C2:C47,"Manufacturing"))/(SUMIFS(Variables!G2:G47, Variables!C2:C47,"Manufacturing")),0) | D18: =IFERROR(B18/C18,"")
A19: Demos / Interested | B19: =IFERROR((SUMIFS(Variables!K2:K47, Variables!C2:C47,"Financial Services 1-5"))/(SUMIFS(Variables!J2:J47, Variables!C2:C47,"Financial Services 1-5")),0) | C19: =IFERROR((SUMIFS(Variables!K2:K47, Variables!C2:C47,"Manufacturing"))/(SUMIFS(Variables!J2:J47, Variables!C2:C47,"Manufacturing")),0) | D19: =IFERROR(B19/C19,"")
A20: SHOW-UPS
A21: Total Show-ups | B21: =SUMIFS(Variables!L2:L47, Variables!C2:C47,"Financial Services 1-5") | C21: =SUMIFS(Variables!L2:L47, Variables!C2:C47,"Manufacturing") | D21: =IFERROR(B21/C21,"")
A22: No-shows | B22: =SUMIFS(Variables!N2:N47, Variables!C2:C47,"Financial Services 1-5") | C22: =SUMIFS(Variables!N2:N47, Variables!C2:C47,"Manufacturing") | D22: =IFERROR(B22/C22,"")
A23: Show-ups / Emails Sent | B23: =IFERROR((SUMIFS(Variables!L2:L47, Variables!C2:C47,"Financial Services 1-5"))/(SUMIFS(Variables!F2:F47, Variables!C2:C47,"Financial Services 1-5")),0) | C23: =IFERROR((SUMIFS(Variables!L2:L47, Variables!C2:C47,"Manufacturing"))/(SUMIFS(Variables!F2:F47, Variables!C2:C47,"Manufacturing")),0) | D23: =IFERROR(B23/C23,"")
A24: Show-ups / Leads Contacted | B24: =IFERROR((SUMIFS(Variables!L2:L47, Variables!C2:C47,"Financial Services 1-5"))/(SUMIFS(Variables!G2:G47, Variables!C2:C47,"Financial Services 1-5")),0) | C24: =IFERROR((SUMIFS(Variables!L2:L47, Variables!C2:C47,"Manufacturing"))/(SUMIFS(Variables!G2:G47, Variables!C2:C47,"Manufacturing")),0) | D24: =IFERROR(B24/C24,"")
A25: Show-up Rate (Shows / Completed) | B25: =IFERROR((SUMIFS(Variables!L2:L47, Variables!C2:C47,"Financial Services 1-5"))/(SUMIFS(Variables!O2:O47, Variables!C2:C47,"Financial Services 1-5")),0) | C25: =IFERROR((SUMIFS(Variables!L2:L47, Variables!C2:C47,"Manufacturing"))/(SUMIFS(Variables!O2:O47, Variables!C2:C47,"Manufacturing")),0) | D25: =IFERROR(B25/C25,"")
